Workbook
Name Al_max: DateIntrare!#REF!
Name Al_min: DateIntrare!#REF!
Name alalv1: DateIntrare!$I$46
Name alalv2: DateIntrare!$I$50
Name alalv3: DateIntrare!$I$54
Name astm: DateIntrare!$A$3
Name C_max: DateIntrare!#REF!
Name cerclient: DateIntrare!#REF!
Name comanda: DateIntrare!$H$3
Name concal1: DateIntrare!#REF!
Name concal2: DateIntrare!$I$62
Name concfe1: DateIntrare!$E$70
Name dozal: RetDozare!#REF!
Name dozfe: RetDozare!#REF!
Name dozo: RetDozare!#REF!
Name dozv: RetDozare!#REF!
Name Fe_max: DateIntrare!#REF!
Name Fe_min: DateIntrare!#REF!
Name feal1: DateIntrare!$E$58
Name feal2: DateIntrare!$E$62
Name fealv1: DateIntrare!$E$46
Name fealv2: DateIntrare!$E$50
Name fealv3: DateIntrare!$E$54
Name feti1: DateIntrare!$E$13
Name feti10: DateIntrare!#REF!
Name feti2: DateIntrare!$E$17
Name feti3: DateIntrare!$E$21
Name feti4: DateIntrare!$E$25
Name feti5: DateIntrare!$E$29
Name feti6: DateIntrare!#REF!
Name feti7: DateIntrare!$E$33
Name feti8: DateIntrare!$E$37
Name feti9: DateIntrare!$E$41
Name fetirest: NA()
Name H_max: DateIntrare!#REF!
Name lotal1: DateIntrare!$B$56
Name lotal2: DateIntrare!$B$60
Name lotalv1: DateIntrare!$B$44
Name lotalv2: DateIntrare!$B$48
Name lotalv3: DateIntrare!$B$52
Name lotfe1: DateIntrare!$B$68
Name lotrest: NA()
Name lotti1: DateIntrare!$B$11
Name lotti10: DateIntrare!#REF!
Name lotti2: DateIntrare!$B$15
Name lotti3: DateIntrare!$B$19
Name lotti4: DateIntrare!$B$23
Name lotti5: DateIntrare!$B$27
Name lotti6: DateIntrare!#REF!
Name lotti7: DateIntrare!$B$31
Name lotti8: DateIntrare!$B$35
Name lotti9: DateIntrare!$B$39
Name lottio2: DateIntrare!$B$75
Name N_max: DateIntrare!#REF!
Name nrpresbara: Bilant!$C$10
Name O_max: DateIntrare!#REF!
Name O_min: DateIntrare!#REF!
Name oxal1: DateIntrare!$D$58
Name oxal2: DateIntrare!$D$62
Name oxalv1: DateIntrare!$D$46

Sheet DateIntrare
A3: Sp. QST4-A-BL543 Revision 00. | G3: Comanda | H3: 26841 | I3: Ti 4321
B4: O min | C4: O max | D4: Fe min | E4: Fe max | F4: C | G4: H max | H4: Al min | I4: Al max | J4: V min | K4: V max | L4: Sn
B5: 0.0008 | C5: 0.0025 | D5: 0.029 | E5: 0.032 | F5: 0.02-0.005% | G5: 0.00012 | H5: 0.044 | I5: 0.048 | J5: 0.019 | K5: 0.023 | L5: 0.015 | M5: 0.018
A6: Tinta | B6: 0.0012 | D6: 0.031 | H6: 0.045 | J6: 0.021 | L6: 0.016
A7: dozare | C7: 0.00098 | D7: 0.031 | H7: Al | I7: 0.0495 | J7: V | K7: 0.0215 | L7: Sn | M7: 0.017
B9: LOT | D9: O | E9: Fe | F9: N | G9: Sn | H9: V | I9: Al | J9: Cant.
J10: [kg]
A11: Ti Burete | B11: 260106-44 | C11: CC | D11: 0.0003 | E11: 0.00013 | J11: 4173 | K11: stc.in.
A12: 1 | C12: BA | J12: 4173 | K12: consum
C13: media | D13: =IF(D12>0,(D11+D12)/2,D11) -> 0.0003 | E13: =IF(E12>0,(E11+E12)/2,E11) -> 0.00013
A15: Ti Burete | B15: 260122-219 | C15: CC | D15: 0.00028 | E15: 4e-05 | J15: 8000 | K15: stc.in.
A16: 2 | C16: BA | J16: 8000 | K16: consum
C17: media | D17: =IF(D16>0,(D15+D16)/2,D15) -> 0.00028 | E17: =IF(E16>0,(E15+E16)/2,E15) -> 4e-05
A19: Ti Burete | B19: 260124-231 | C19: CC | D19: 0.00022 | E19: 0.00017 | J19: 7750 | K19: stc.in.
A20: 3 | C20: BA | J20: =J19-J21 -> 904.37186 | K20: consum
C21: media | D21: =IF(D20>0,(D19+D20)/2,D19) -> 0.00022 | E21: =IF(E20>0,(E19+E20)/2,E19) -> 0.00017 | J21: =RetDozare!I163 -> 6845.6281
A23: Ti Burete | C23: CC | K23: stc.in.
A24: 4 | C24: BA | K24: consum
C25: media | K25: rest
A27: Ti Burete | C27: CC | K27: stc.in.
A28: 5 | C28: BA | K28: consum
C29: media | K29: stc.in.
A31: Ti Burete | C31: CC | J31: 2000 | K31: stc.in.
A32: 6 | B32: TG90 | C32: BA | K32: consum
B33: -30+10 | C33: media | D33: =IF(D32>0,(D31+D32)/2,D31) -> 0 | E33: =IF(E32>0,(E31+E32)/2,E31) -> 0 | K33: rest
A35: Ti Burete | C35: CC | K35: stc.in.
A36: 7 | B36: TG100 | C36: BA | K36: consum
B37: -30+10 | C37: media | D37: =IF(D36>0,(D35+D36)/2,D35) -> 0 | E37: =IF(E36>0,(E35+E36)/2,E35) -> 0 | F37: =IF(F36>0,(F35+F36)/2,F35) -> 0 | G37: =IF(G36>0,(G35+G36)/2,G35) -> 0 | J37: 0 | K37: rest
A39: Ti Burete | C39: CC | J39: 1750 | K39: stc.in.
A40: 8 | B40: TG100 | C40: BA | J40: 1750 | K40: consum
B41: -30+10 | C41: media | D41: =IF(D40>0,(D39+D40)/2,D39) -> 0 | E41: =IF(E40>0,(E39+E40)/2,E39) -> 0 | F41: =IF(F40>0,(F39+F40)/2,F39) -> 0 | G41: =IF(G40>0,(G39+G40)/2,G39) -> 0 | K41: rest
A44: Aliaj AlV | B44: 355130 | C44: CC | D44: 0.0004 | E44: 0.002 | H44: 0.657 | I44: 0.338 | J44: 350 | K44: stc.in.
A45: 1 | B45: GfE | C45: BA | J45: 350 | K45: consum
C46: media | D46: =IF(D45>0,(D44+D45)/2,D44) -> 0.0004 | E46: =IF(E45>0,(E44+E45)/2,E44) -> 0.002 | H46: =IF(H45>0,(H44+H45)/2,H44) -> 0.657 | I46: =IF(I45>0,(I44+I45)/2,I44) -> 0.338 | K46: rest
A48: Aliaj AlV | B48: 347445 | C48: CC | D48: 0.0005 | E48: 0.002 | H48: 0.655 | I48: 0.341 | J48: 1360.8 | K48: stc.in.
A49: 2 | B49: GfE | C49: BA | J49: =J48-J50 -> 111.11276 | K49: consum
C50: media | D50: =IF(D49>0,(D48+D49)/2,D48) -> 0.0005 | E50: =IF(E49>0,(E48+E49)/2,E48) -> 0.002 | H50: =IF(H49>0,(H48+H49)/2,H48) -> 0.655 | I50: =IF(I49>0,(I48+I49)/2,I48) -> 0.341 | J50: =RetDozare!J163 -> 1249.6872 | K50: rest
A52: Aliaj AlV | C52: CC | K52: stc.in.
A53: 3 | C53: BA | K53: consum
C54: media | D54: =IF(D53>0,(D52+D53)/2,D52) -> 0 | E54: =IF(E53>0,(E52+E53)/2,E52) -> 0 | H54: =IF(H53>0,(H52+H53)/2,H52) -> 0 | I54: =IF(I53>0,(I52+I53)/2,I52) -> 0 | K54: rest
...

Sheet Bilant
A3: =astm -> Sp. QST4-A-BL543 Revision 00. | G3: Comanda | H3: =comanda -> 26841 | I3: Bilant teoretic
B4: O min | C4: O max | D4: Fe min | E4: Fe max | F4: C | G4: H max | H4: Al min | I4: Al max | J4: V min | K4: V max | L4: Sn
B5: 0.0008 | C5: 0.0025 | D5: 0.029 | E5: 0.032 | F5: 0.02-0.005% | G5: 0.00012 | H5: 0.044 | I5: 0.048 | J5: 0.019 | K5: 0.023 | L5: 0.015 | M5: 0.018
A6: dozare | C6: 0.00098 | D6: 0.031 | H6: Al | I6: 0.0495 | J6: V | K6: 0.0215 | L6: Sn | M6: 0.017
A8: Tehnologie de prelucrare: presare d=350; VAR1 d=440;VAR2 d=500;VAR3 d=600 mm
C9: Intrare | D9: Iesire | F9: Titan R | G9: Deseu | H9: Pierd | K9: Conc.in bara
A10: Pres | B10: P [nr] | C10: 22 | D10: 4 | K10: =I6 -> 0.0495 | L10: Al
B11: [Kg/portie] | C11: 40 | K11: =K6 -> 0.0215 | L11: V
B12: D[mm] | D12: 0.35 | K12: =C6 -> 0.00098 | L12: O
B13: L[mm] | D13: =4*D14/(3.14*D12^2*4430*0.74) -> 2.7915247 | K13: =D6 -> 0.031 | L13: Fe
B14: [Kg] | D14: =C11*nrpresbara -> 880 | H14: 0.2 | K14: =M6 -> 0.017 | L14: Sn
A15: Sudura I | B15: [buc./semib.] | C15: =IF(C10>22,2,1) -> 1 | D15: 1
B16: [Kg] | C16: =IF(C10>22,D14/C15,D14) -> 880 | D16: =C16*C15 -> 880
A17: Top I | D17: =D10 -> 4 | E17: Lingou LI | I17: Topit. | K17: Prealiaj AlV
B18: D[mm] | C18: =D12 -> 0.35 | D18: 0.44 | I18: =D18+0.01 -> 0.45 | K18: lot | L18: 355130
B19: L[mm] | C19: =D13 -> 2.7915247 | D19: =D20*4/(D18^2*3.14*4450) -> 1.2952962 | I19: =D19/0.95 -> 1.3634697 | K19: =alalv1 -> 0.338 | L19: Al
B20: [Kg] | C20: =D16 -> 880 | D20: =C20+C21-H20 -> 876 | H20: 5 | I20: =D20 -> 876 | K20: =valv1 -> 0.657 | L20: V
B21: Amrs | C21: 1 | G21: Stub | H21: 2 | K21: =IF(L18=lotalv1,oxalv1,IF(L18=lotalv2,oxalv2,"ERR LOT")) -> 0.0004 | L21: O
A22: Strnj I | B22: D[mm] | C22: =D18 -> 0.44 | D22: =C22-0.005 -> 0.435 | K22: =IF(L18=lotalv1,fealv1,IF(L18=lotalv2,fealv2,"ERR LOT")) -> 0.002 | L22: Fe
B23: L[mm] | C23: =D19 -> 1.2952962 | D23: =C23-0.002 -> 1.2932962
B24: [Kg] | C24: =D20 -> 876 | D24: =3.14*D22^2/4*D23*4450 -> 854.88201 | E24: Sp. I | G24: =D20-D24 -> 21.117992
A25: Sudura II | C25: 2 | D25: 1
C26: =D24 -> 854.88201 | D26: =C26*C25 -> 1709.764
A27: Top II | D27: 1 | E27: Lingou LII | I27: Topit.
B28: D[mm] | C28: =D22 -> 0.435 | D28: 0.49 | I28: =D28+0.01 -> 0.5
B29: L[mm] | C29: =D23*C25 -> 2.5865924 | D29: =D30*4/(D28^2*3.14*4450) -> 2.0337479 | I29: =D29/0.95 -> 2.1407873
B30: [Kg] | C30: =D26 -> 1709.764 | D30: =C30+C31-H30 -> 1705.764 | H30: 5 | I30: =D30 -> 1705.764
B31: Amrs | C31: 1 | G31: Stub | H31: 3
A32: Strnj II | B32: D[mm] | C32: =D28 -> 0.49 | D32: 0.488
B33: L[mm] | C33: =D29 -> 2.0337479 | D33: =C33-0.002 -> 2.0317479
B34: [Kg] | C34: =D30 -> 1705.764 | D34: =3.14*D32^2/4*D33*4450 -> 1690.204 | E34: Sp. R, I | F34: =(C34-D34)*3/4 -> 11.669985 | G34: =(C34-D34)*1/4 -> 3.8899949
A35: Sudura III | C35: 2 | D35: 1
C36: =D34 -> 1690.204 | D36: =C36*C35 -> 3380.4081
A37: Top III | D37: 1 | I37: Topit.
B38: D[mm] | C38: =D32 -> 0.488 | D38: 0.59 | E38: Lingou LIII | I38: =D38+0.01 -> 0.6
B39: L[mm] | C39: =D33*C35 -> 4.0634958 | D39: =D40*4/(D38^2*3.14*4450) -> 2.7766506 | I39: =D39/0.95 -> 2.9227901
B40: [Kg] | C40: =D36 -> 3380.4081 | D40: =C40+C41-H40 -> 3376.4081 | H40: 5 | I40: =D40 -> 3376.4081
B41: Amrs | C41: 1 | H41: 3
A42: Strnj II | B42: D[mm] | C42: =D38 -> 0.59 | D42: 0.588
B43: L[mm] | C43: =D39 -> 2.7766506 | D43: =C43-0.002 -> 2.7746506
...

Sheet RetDozare
A4: =astm -> Sp. QST4-A-BL543 Revision 00. | G4: Cmnd. | H4: 26841 | J4: Reteta | K4: 1
B5: O min | C5: O max | D5: Fe min | E5: Fe max | F5: C | G5: H max | H5: Al min | I5: Al max | J5: V min | K5: V max | L5: Sn
B6: 0.0008 | C6: 0.0025 | D6: 0.029 | E6: 0.032 | F6: 0-0.02% | G6: 0-0.012% | H6: 0.044 | I6: 0.048 | J6: 0.019 | K6: 0.023 | L6: 0.015 | M6: 0.018
A7: Tinta | B7: 0.0012 | D7: 0.031 | F7: 5e-05 | G7: LAP | H7: 0.045 | J7: 0.021 | L7: 0.016
A8: dozare | C8: 0.00098 | D8: 0.031 | H8: Al | I8: 0.0495 | J8: V | K8: 0.0215 | L8: Sn | M8: 0.017
A10: Burete Ti | C10: 260106-44 | D10: =DateIntrare!J11 -> 4173 | E10: 0.9974 | I10: Bilant presare [Kg]
A11: Prealiaj V Al | C11: 355130 | D11: =DateIntrare!J44 -> 350 | I11: Ti | J11: AlV | K11: Al | L11: TiO2 | M11: Sn | N11: Fe
A12: Al (metal) | C12: W66057809 | D12: =DateIntrare!J56 -> 1730 | E12: =DateIntrare!I56 -> 0.9986 | H12: B 1 | I12: =D10 -> 4173 | J12: =D11 -> 350 | K12: =D12 -> 1730 | L12: =D14 -> 985 | M12: =D15 -> 50 | N12: =D13 -> 866.95
A13: Fe (metal) | C13: 4430521 | D13: =DateIntrare!J68 -> 866.95 | H13: B 2 | I13: =I12-B36 -> 3355.6714 | J13: =J12-C36 -> 321.20244 | K13: =K12-D36 -> 1696.1262 | L13: =L12-E36 -> 983.48579 | M13: =M12-G36 -> 34.888889 | N13: =N12-F36 -> 839.55995
A14: TiO2 (pulv.) | C14: LOT 0087718 | D14: =DateIntrare!J75 -> 985 | H14: B 3 | I14: =I13-B36 -> 2538.3428 | J14: =J13-C36 -> 292.40487 | K14: =K13-D36 -> 1662.2523 | L14: =L13-E36 -> 981.97159 | M14: =M13-G36 -> 19.777778 | N14: =N13-F36 -> 812.16989
A15: Sn met | C15: NIR 25.21071 | D15: =DateIntrare!J60 -> 50 | E15: 0.99 | H15: B 4 | I15: =I14-B36 -> 1721.0142 | J15: =J14-C36 -> 263.60731 | K15: =K14-D36 -> 1628.3785 | L15: =L14-E36 -> 980.45738 | M15: =M14-G36 -> 4.6666667 | N15: =N14-F36 -> 784.77984
I16: =I15-B36 -> 903.68564 | J16: =J15-C36 -> 234.80974 | K16: =K15-D36 -> 1594.5046 | L16: =L15-E36 -> 978.94318 | M16: =M15-G36 -> -10.444444 | N16: =N15-F36 -> 757.38979
A19: Initial | B19: Burete Ti | C19: Aliaj Al V | D19: Al metal | E19: TiO2 | F19: Fe metal | G19: Sn metal
A20: [%] Ti | B20: =E10 -> 0.9974 | E20: =1-E23 -> 0.6
A21: [%] Al | C21: =IF(C11=lotalv1,alalv1,IF(C11=lotalv2,alalv2,"ERR LOT")) -> 0.338 | D21: =E12 -> 0.9986
A22: [%] V | C22: =IF(C11=lotalv1,valv1,IF(C11=lotalv2,valv2,"ERR LOT")) -> 0.657
A23: [%] O | B23: =IF(C10=lotti1,oxti1,IF(C10=lotti2,oxti2,IF(C10=lotti3,oxti3,IF(C10=lotti4,oxti4,IF(C10=lotti5,oxti5,IF(C10=lotti6,oxti6,IF(C10=lotti7,oxti7,IF(C10=lotti8,oxti8,"ERR LOT")))))))) -> 0.0003 | C23: =IF(C11=lotalv1,oxalv1,IF(C11=lotalv2,oxalv2,"ERR LOT")) -> 0.0004 | D23: =IF(C12=lotal1,oxal1,IF(C12=lotal2,oxal2,"ERR LOT")) -> 0 | E23: =IF(C14=lottio2,oxtio2,"err LOT") -> 0.4
A24: [%] Fe | B24: =IF(C10=lotti1,feti1,IF(C10=lotti2,feti2,IF(C10=lotti3,feti3,IF(C10=lotti4,feti4,IF(C10=lotti5,feti5,IF(C10=lotti6,feti6,IF(C10=lotti7,feti7,IF(C10=lotti8,feti8,"ERR LOT")))))))) -> 0.00013 | C24: =IF(C11=lotalv1,fealv1,IF(C11=lotalv2,fealv2,"ERR LOT")) -> 0.002 | D24: =IF(C12=lotal1,feal1,IF(C12=lotal2,feal2,"ERR LOT")) -> 0.00083 | F24: 0.99
A25: [%] Sn | G25: =DateIntrare!G62 -> 0.99
A28: Concentratii In bara | B28: Ti | C28: V | D28: Al | E28: O | F28: Fe | G28: Sn
B29: bal. | C29: =K8 -> 0.0215 | D29: =I8 -> 0.0495 | E29: =C8 -> 0.00098 | F29: =D8 -> 0.031 | G29: =M8 -> 0.017
A31: DOZARE PORTIE [Kg]
A32: PORTIE | B32: Burete Ti | C32: Aliaj Al V | D32: Al metal | E32: TiO2 | F32: Fe metal | G32: Sn metal
A33: 40 | B33: =A33-C33-D33 -> 37.151299 | C33: =A33*C29/C22 -> 1.3089802 | D33: =(A33*D29-C33*C21)/D21 -> 1.5397203 | E33: =(A33*E29-B33*B23-C33*C23-D33*D23)/E23 -> 0.068827545 | F33: =(A33*F29-B33*B24-C33*C24)/F24 -> 1.2450024 | G33: =A33*G29/G25 -> 0.68686869
A34: 20 | B34: =A34-C34-D34 -> 18.576728 | C34: =A34*C29/C22 -> 0.65449011 | D34: =A34*D29-C34*C21 -> 0.76878234 | E34: =(A34*E29-B34*B24-C34*C24-D34*D24)/E23 -> 0.03809489 | F34: 0
A36: =A33*J36 -> 880 | B36: =B33*J36 -> 817.32859 | C36: =C33*J36 -> 28.797565 | D36: =D33*J36 -> 33.873847 | E36: =E33*J36 -> 1.514206 | F36: =F33*J36 -> 27.390053 | G36: =G33*J36 -> 15.111111 | I36: Nr.Pres. | J36: 22
A41: =astm -> Sp. QST4-A-BL543 Revision 00. | G41: Cmnd. | H41: 26841 | J41: Reteta | K41: 2
B42: O min | C42: O max | D42: Fe min | E42: Fe max | F42: C | G42: H max | H42: Al min | I42: Al max | J42: V min | K42: V max | L42: Sn
B43: 0.0008 | C43: 0.0025 | D43: 0.029 | E43: 0.032 | F43: 0-0.02% | G43: 0-0.012% | H43: 0.044 | I43: 0.048 | J43: 0.019 | K43: 0.023 | L43: 0.015 | M43: 0.018
A44: Tinta | B44: 0.0012 | D44: 0.031 | F44: 5e-05 | G44: LAP | H44: 0.045 | J44: 0.021 | L44: 0.016
A45: dozare | C45: 0.00098 | D45: 0.031 | H45: Al | I45: 0.0495 | J45: V | K45: 0.0215 | L45: Sn | M45: 0.017
A47: Burete Ti | C47: 260106-44 | D47: =I15 -> 1721.0142 | E47: 0.9974 | I47: Bilant presare [Kg]
A48: Prealiaj V Al | C48: 355130 | D48: =J15 -> 263.60731 | I48: Ti | J48: AlV | K48: Al | L48: TiO2 | M48: Sn | N48: Fe
A49: Al (metal) | C49: W66057809 | D49: =K15 -> 1628.3785 | E49: 0.9986 | H49: B 4 | I49: =D47 -> 1721.0142 | J49: =D48 -> 263.60731 | K49: =D49 -> 1628.3785 | L49: =D51 -> 980.45738 | M49: =D52+M15 -> 258.66667 | N49: =D50 -> 784.77984
A50: Fe (metal) | C50: 4430521 | D50: =N15 -> 784.77984 | H50: B 5 | I50: =I49-B73 -> 903.68564 | J50: =J49-C73 -> 234.80974 | K50: =K49-D73 -> 1594.5046 | L50: =L49-E73 -> 978.94318 | M50: =M49-G73 -> 243.55556 | N50: =N49-F73 -> 757.38979
A51: TiO2 (pulv.) | C51: LOT 0087718 | D51: =L15 -> 980.45738 | H51: B 6 | I51: =I50-B73 -> 86.357056 | J51: =J50-C73 -> 206.01218 | K51: =K50-D73 -> 1560.6308 | L51: =L50-E73 -> 977.42897 | M51: =M50-G73 -> 228.44444 | N51: =N50-F73 -> 729.99974
A52: Sn met | C52: 26.21035 | D52: =DateIntrare!J64 -> 254 | E52: 0.99 | I52: =I51-B73 -> -730.97153 | J52: =J51-C73 -> 177.21461 | K52: =K51-D73 -> 1526.7569 | L52: =L51-E73 -> 975.91476 | M52: =M51-G73 -> 213.33333 | N52: =N51-F73 -> 702.60968
A56: Initial | B56: Burete Ti | C56: Aliaj Al V | D56: Al metal | E56: TiO2 | F56: Fe metal | G56: Sn metal
A57: [%] Ti | B57: =E47 -> 0.9974 | E57: =1-E60 -> 0.6
A58: [%] Al | C58: =IF(C48=lotalv1,alalv1,IF(C48=lotalv2,alalv2,"ERR LOT")) -> 0.338 | D58: =E49 -> 0.9986
...
