Workbook
Name Al_max: DateIntrare!#REF!
Name Al_min: DateIntrare!#REF!
Name alalv1: DateIntrare!$I$47
Name alalv2: DateIntrare!$I$51
Name alalv3: DateIntrare!$I$55
Name astm: DateIntrare!$A$3
Name C_max: DateIntrare!#REF!
Name cerclient: DateIntrare!#REF!
Name comanda: DateIntrare!$H$3
Name concal1: DateIntrare!#REF!
Name concal2: DateIntrare!$I$67
Name concfe1: DateIntrare!$E$71
Name dozal: RetDozare!#REF!
Name dozfe: RetDozare!#REF!
Name dozo: RetDozare!#REF!
Name dozv: RetDozare!#REF!
Name Fe_max: DateIntrare!#REF!
Name Fe_min: DateIntrare!#REF!
Name feal1: DateIntrare!$E$63
Name feal2: DateIntrare!$E$67
Name fealv1: DateIntrare!$E$47
Name fealv2: DateIntrare!$E$51
Name fealv3: DateIntrare!$E$55
Name feti1: DateIntrare!$E$14
Name feti10: DateIntrare!#REF!
Name feti2: DateIntrare!$E$18
Name feti3: DateIntrare!$E$22
Name feti4: DateIntrare!$E$26
Name feti5: DateIntrare!$E$30
Name feti6: DateIntrare!#REF!
Name feti7: DateIntrare!$E$34
Name feti8: DateIntrare!$E$38
Name feti9: DateIntrare!$E$42
Name fetirest: NA()
Name H_max: DateIntrare!#REF!
Name lotal1: DateIntrare!$B$61
Name lotal2: DateIntrare!$B$65
Name lotalv1: DateIntrare!$B$45
Name lotalv2: DateIntrare!$B$49
Name lotalv3: DateIntrare!$B$53
Name lotfe1: DateIntrare!$B$69
Name lotrest: NA()
Name lotti1: DateIntrare!$B$12
Name lotti10: DateIntrare!#REF!
Name lotti2: DateIntrare!$B$16
Name lotti3: DateIntrare!$B$20
Name lotti4: DateIntrare!$B$24
Name lotti5: DateIntrare!$B$28
Name lotti6: DateIntrare!#REF!
Name lotti7: DateIntrare!$B$32
Name lotti8: DateIntrare!$B$36
Name lotti9: DateIntrare!$B$40
Name lottio2: DateIntrare!$B$73
Name N_max: DateIntrare!#REF!
Name nrpresbara: Bilant!$C$10
Name O_max: DateIntrare!#REF!
Name O_min: DateIntrare!#REF!
Name oxal1: DateIntrare!$D$63
Name oxal2: DateIntrare!$D$67
Name oxalv1: DateIntrare!$D$47

Sheet DateIntrare
G3: Comanda | H3: 25840
C4: Al | E4: Mo | G4: Zr | I4: Nb | K4: O | M4: Sn | O4: Si | P4: C
C5: 0.055 | D5: 0.061 | E5: 0.0025 | F5: 0.0075 | G5: 0.03 | H5: 0.05 | I5: 0.005 | J5: 0.01 | K5: 0.00075 | L5: 0.0015 | M5: 0.03 | N5: 0.05 | O5: 0.2-0.6% | P5: 0.04-0.08
A6: Dozare in bara | C6: Al | D6: 0.059 | E6: Mo | F6: 0.005 | G6: Zr | H6: 0.04 | I6: Nb | J6: 0.0008 | K6: O | L6: 0.00105 | M6: Sn | N6: 0.04 | O6: 0.004 | P6: 0.0007
B10: LOT | D10: O | E10: Nb | F10: Si | G10: Sn | H10: Zr | I10: Mo | J10: Al | K10: C | L10: Cantitate
A12: Ti Burete | B12: S-24020009 | C12: CC | D12: 0.0003 | L12: 6768 | M12: stc.in.
A13: 1 | C13: BA | L13: =L12-L14 -> 135.50221 | M13: consum
C14: media | D14: =IF(D13>0,(D12+D13)/2,D12) -> 0.0003 | L14: =RetDozare!B34 -> 6632.4978
A16: Ti Burete | C16: CC | M16: stc.in.
A17: 2 | C17: BA | M17: consum
C18: media
A20: Ti Burete | C20: CC | M20: stc.in.
A21: 3 | C21: BA | M21: consum
C22: media
A24: Ti Burete | C24: CC | M24: stc.in.
A25: 4 | C25: BA | M25: consum
C26: media | M26: rest
A28: Ti Burete | C28: CC | M28: stc.in.
A29: 5 | C29: BA | M29: consum
C30: media | M30: stc.in.
A32: Ti Burete | C32: CC | L32: 2000 | M32: stc.in.
A33: 6 | B33: TG90 | C33: BA | M33: consum
B34: -30+10 | C34: media | D34: =IF(D33>0,(D32+D33)/2,D32) -> 0 | E34: =IF(E33>0,(E32+E33)/2,E32) -> 0 | M34: rest
A36: Ti Burete | C36: CC | M36: stc.in.
A37: 7 | B37: TG100 | C37: BA | M37: consum
B38: -30+10 | C38: media | D38: =IF(D37>0,(D36+D37)/2,D36) -> 0 | E38: =IF(E37>0,(E36+E37)/2,E36) -> 0 | F38: =IF(F37>0,(F36+F37)/2,F36) -> 0 | G38: =IF(G37>0,(G36+G37)/2,G36) -> 0 | L38: 0 | M38: rest
A40: Ti Burete | C40: CC | L40: 1750 | M40: stc.in.
A41: 8 | B41: TG100 | C41: BA | L41: 1750 | M41: consum
B42: -30+10 | C42: media | D42: =IF(D41>0,(D40+D41)/2,D40) -> 0 | E42: =IF(E41>0,(E40+E41)/2,E40) -> 0 | F42: =IF(F41>0,(F40+F41)/2,F40) -> 0 | G42: =IF(G41>0,(G40+G41)/2,G40) -> 0 | M42: rest
A45: AlMo35/65 | B45: 310301 | C45: CC | D45: 0.0009 | I45: 0.651 | J45: 0.347 | L45: 342 | M45: stc.in.
B46: GfE | C46: BA | L46: =L45-L47 -> 1.2288786 | M46: consum
C47: media | D47: =IF(D46>0,(D45+D46)/2,D45) -> 0.0009 | I47: =IF(I46>0,(I45+I46)/2,I45) -> 0.651 | J47: =IF(J46>0,(J45+J46)/2,J45) -> 0.347 | K47: =IF(K46>0,(K45+K46)/2,K45) -> 0 | L47: =RetDozare!C34 -> 340.77112 | M47: rest
A49: Aliaj AlV | C49: CC | D49: 0.00068 | E49: 0.0014 | H49: 0.6375 | I49: 0.355 | L49: 270 | M49: stc.in.
A50: 2 | C50: BA | H50: 0.6316 | I50: 0.3625 | L50: =L49-L51 -> 270 | M50: consum
C51: media | D51: =IF(D50>0,(D49+D50)/2,D49) -> 0.00068 | E51: =IF(E50>0,(E49+E50)/2,E49) -> 0.0014 | H51: =IF(H50>0,(H49+H50)/2,H49) -> 0.63455 | I51: =IF(I50>0,(I49+I50)/2,I49) -> 0.35875 | M51: rest
A53: Aliaj AlV | C53: CC | M53: stc.in.
A54: 3 | C54: BA | M54: consum
C55: media | D55: =IF(D54>0,(D53+D54)/2,D53) -> 0 | E55: =IF(E54>0,(E53+E54)/2,E53) -> 0 | H55: =IF(H54>0,(H53+H54)/2,H53) -> 0 | I55: =IF(I54>0,(I53+I54)/2,I53) -> 0 | M55: rest
B56: lot 73664 | C56: CC | D56: 0.00079 | E56: 0.595 | J56: 0.4025 | L56: 400
A57: AlNb | C57: BA | L57: =L56-L58 -> 0.21512605
...

Sheet Bilant
A3: =astm -> 0 | G3: Comanda | H3: =comanda -> 25840 | I3: Bilant teoretic
B4: O min | C4: O max | D4: Fe max | E4: N max | F4: C max | G4: H max | H4: Al min | I4: Al max | J4: V min | K4: V max
A5: ASTM B348-13 | B5: =DateIntrare!#REF! -> #REF! | C5: =DateIntrare!#REF! -> #REF! | D5: =DateIntrare!#REF! -> #REF! | E5: =DateIntrare!#REF! -> #REF! | F5: =DateIntrare!#REF! -> #REF! | G5: =DateIntrare!#REF! -> #REF! | H5: =DateIntrare!#REF! -> #REF! | I5: =DateIntrare!#REF! -> #REF! | ... K5: =DateIntrare!#REF! -> #REF!
A6: Dozare | B6: =DateIntrare!#REF! -> #REF! | C6: 0.00095 | D6: 0.00087 | H6: =DateIntrare!#REF! -> #REF! | I6: =DateIntrare!#REF! -> #REF! | J6: =DateIntrare!#REF! -> #REF! | K6: =DateIntrare!#REF! -> #REF!
A8: Tehnologie de prelucrare: presare d=350; VAR1 d=500;
C9: Intrare | D9: Iesire | F9: Titan R | G9: Deseu | H9: Pierd | K9: Conc.in bara
A10: Pres | B10: P [nr] | C10: 17 | D10: 2 | K10: 0.0297 | L10: Al
B11: [Kg/portie] | C11: 40 | K11: 0.025 | L11: V
B12: D[mm] | D12: 0.35 | K12: 0.00095 | L12: O
B13: L[mm] | D13: =4*D14/(3.14*D12^2*4430*0.74) -> 2.1570873 | K13: 0.00087 | L13: Fe
B14: [Kg] | D14: =C11*nrpresbara -> 680 | H14: 0.2
A15: Sudura I | B15: [buc./semib.] | C15: =IF(C10>22,2,1) -> 1 | D15: 1 | K15: Prealiaj AlV
B16: [Kg] | C16: =IF(C10>22,D14/C15,D14) -> 680 | D16: =C16*C15 -> 680 | K16: lot | L16: lot 298905
A17: Top I | D17: =D10 -> 2 | E17: Lingou LI | I17: Topit. | K17: =alalv1 -> 0.651 | L17: Al
B18: D[mm] | C18: =D12 -> 0.35 | D18: 0.49 | I18: =D18+0.01 -> 0.5 | K18: =valv1 -> 0 | L18: V
B19: L[mm] | C19: =D13 -> 2.1570873 | D19: =D20*4/(D18^2*3.14*4450) -> 0.82863443 | I19: =D19/0.95 -> 0.87224677 | K19: =IF(L16=lotalv1,oxalv1,IF(L16=lotalv2,oxalv2,"ERR LOT")) -> ERR LOT | L19: O
B20: [Kg] | C20: =D16 -> 680 | D20: =C20+C21-H20 -> 695 | H20: 5 | I20: =D20 -> 695 | K20: =IF(L16=lotalv1,fealv1,IF(L16=lotalv2,fealv2,"ERR LOT")) -> ERR LOT | L20: Fe
B21: Amrs | C21: 20 | G21: Stub | H21: 2
A22: Strnj I | B22: D[mm] | C22: =D18 -> 0.49 | D22: =C22-0.005 -> 0.485
B23: L[mm] | C23: =D19 -> 0.82863443 | D23: =C23-0.002 -> 0.82663443
B24: [Kg] | C24: =D20 -> 695 | D24: =3.14*D22^2/4*D23*4450 -> 679.24529 | E24: Sp. I | G24: =D20-D24 -> 15.754707
A25: Sudura II | C25: =D10 -> 2 | D25: 1
C26: =D24 -> 679.24529 | D26: =C26*C25 -> 1358.4906
A27: Top II | D27: 1 | E27: Lingou LII | I27: Topit.
B28: D[mm] | C28: =D22 -> 0.485 | D28: 0.59 | I28: =D28+0.01 -> 0.6
B29: L[mm] | C29: =D23*C25 -> 1.6532689 | D29: =D30*4/(D28^2*3.14*4450) -> 1.1196466 | I29: =D29/0.95 -> 1.1785753
B30: [Kg] | C30: =D26 -> 1358.4906 | D30: =C30+C31-H30 -> 1361.4906 | H30: 5 | I30: =D30 -> 1361.4906
B31: Amrs | C31: 8 | G31: Stub | H31: 3
A32: Strnj II | B32: D[mm] | C32: =D28 -> 0.59 | D32: 0.575
B33: L[mm] | C33: =D29 -> 1.1196466 | D33: =C33-0.004 -> 1.1156466
B34: [Kg] | C34: =D30 -> 1361.4906 | D34: =3.14*D32^2/4*D33*4450 -> 1288.5224 | E34: Sp. R, I | F34: =(C34-D34)*3/4 -> 54.726103 | G34: =(C34-D34)*1/4 -> 18.242034
A35: Debit II | B35: D[mm] | C35: =D32 -> 0.575 | D35: =C35 -> 0.575
B36: L[mm] | C36: =D33 -> 1.1156466 | D36: =C36-D39-D42-0.006 -> 0.93964656
B37: [Kg] | C37: =D34 -> 1288.5224 | D37: =3.14*D35^2/4*D36*4450 -> 1085.2502 | E37: Sp.I | G37: =3.14*D35^2/4*0.006*4450 -> 6.9297347
A38: Cap | B38: D[mm] | D38: =D35 -> 0.575
B39: L[mm] | D39: 0.12
B40: [Kg] | D40: =3.14*D38^2/4*D39*4450 -> 138.59469 | E40: Cap R | F40: =D40 -> 138.59469
A41: Picior II R | B41: D[mm] | D41: =D35 -> 0.575
B42: L[mm] | D42: 0.05
B43: [Kg] | D43: =3.14*D41^2/4*D42*4450 -> 57.747789 | E43: Pic. II R | F43: =D43 -> 57.747789
...

Sheet RetDozare
H3: Comanda | I3: 25840 | J3: Ti 834 | L3: Reteta 1
C4: Al | E4: Mo | G4: Zr | I4: Nb | K4: O | M4: Sn | O4: Si | P4: C
C5: 0.055 | D5: 0.061 | E5: 0.0025 | F5: 0.0075 | G5: 0.03 | H5: 0.05 | I5: 0.005 | J5: 0.01 | K5: 0.00075 | L5: 0.0015 | M5: 0.03 | N5: 0.05 | O5: 0.2-0.6% | P5: 0.04-0.08
A6: Dozare in bara | C6: Al | D6: 0.059 | E6: Mo | F6: 0.005 | G6: Zr | H6: 0.04 | I6: Nb | J6: 0.0008 | K6: O | L6: 0.00105 | M6: Sn | N6: 0.04 | O6: 0.004 | P6: 0.0007
A8: Materii prime - compozitie chimica [%] | M8: Cant.
B9: Lot | C9: Ti | D9: Mo | E9: Al | F9: Nb | G9: Zr | H9: O | I9: Sn | J9: Si | K9: C | M9: [Kg]
A10: Ti burete | B10: S-24020009 | H10: =oxti1 -> 0.0003 | M10: 6768
A11: AlMo35/65 | B11: 310301 | D11: 0.651 | E11: 0.347 | H11: 0.0009 | M11: 342 | Q11: 0.4025
A12: Al met. | B12: W65045619 | E12: 0.9982 | M12: 1770 | Q12: 0.595
A13: AlNb 40/60 | B13: lot 73664 | E13: 0.4025 | F13: 0.595 | H13: 0.00079 | M13: 400 | Q13: 0.00079
A14: Sn met. | B14: lot MTX 20 1217 | I14: 0.9996 | M14: 291
A16: TiSi | B16: lot 319253 | C16: 40.84% | J16: 0.615 | M16: 20.2
A17: TiO2 | B17: LOT 0066804 | C17: 0.6 | H17: 0.4 | M17: 486
A18: Zr 702 | B18: 24.21032 | G18: 0.9763 | M18: 10
A19: Grafit pulb | B19: C | K19: 0.9989 | M19: 0.4
A22: Concentratii prescrise in bara in bara [%]
A23: Element aliere | C23: Ti | D23: Mo | E23: Al | F23: Nb | G23: Zr | H23: Si | I23: O | J23: Sn | K23: C
A24: Conc. | C24: =100%-D24-E24-F24-G24-H24-J24-K24 -> 0.8505 | D24: =F6 -> 0.005 | E24: =D6 -> 0.059 | F24: =J6 -> 0.0008 | G24: =H6 -> 0.04 | H24: =O6 -> 0.004 | I24: =L6 -> 0.00105 | J24: 0.04 | K24: =P6 -> 0.0007
A25: Dozare in bara [Kg]
C26: Ti burete | D26: AlMo | E26: Al met. | F26: AlNb | G26: Zr | H26: TiSi | I26: TiO2 | J26: Sn | K26: C
B27: 10 | C27: =B27-D27-E27-F27-G27-H27-J27-K27 -> 8.4688881 | D27: =B27*D24/D11 -> 0.076804916 | E27: =(B27*E24-D27*E11-F27*E13)/E12 -> 0.55894303 | F27: =B27*F24/F13 -> 0.013445378 | G27: =B27*G24/G18 -> 0.40971013 | H27: =B27*H24/J16 -> 0.06504065 | I27: =B27*I24/H17-C27*H10-D27*H11-E27*H13-F27*H14-G27*H15-H27*H16 -> 0.023198644 | J27: =B27*J24/I14 -> 0.40016006 | K27: =B27*K24/K19 -> 0.0070077085
A28: Portie | B28: 40 | C28: =C27*B28/B27 -> 33.875553 | D28: =D27*B28/B27 -> 0.30721966 | E28: =E27*B28/B27 -> 2.2357721 | F28: =F27*B28/B27 -> 0.053781513 | G28: =G27*B28/B27 -> 1.6388405 | H28: =H27*B28/B27 -> 0.2601626 | I28: =B28*I27/B27 -> 0.092794577 | J28: =B28*J27/B27 -> 1.6006403 | K28: =B28*K27/B27 -> 0.028030834 | N28: Nr.Prs.
B29: =B28*N29 -> 160 | C29: =C28*N29 -> 135.50221 | D29: =D28*N29 -> 1.2288786 | E29: =E28*N29 -> 8.9430884 | F29: =F28*N29 -> 0.21512605 | G29: =G28*N29 -> 6.5553621 | H29: =H28*N29 -> 1.0406504 | I29: =I28*N29 -> 0.37117831 | J29: =J28*N29 -> 6.402561 | K29: =K28*N29 -> 0.11212334 | N29: 4
A32: Bara | B32: =A10 -> Ti burete | C32: =A11 -> AlMo35/65 | D32: =A12 -> Al met. | E32: Zr | F32: Sn | G32: AlNb | H32: =A17 -> TiO2 | I32: Si | J32: C
A33: B1 | B33: =M10 -> 6768 | C33: =M11 -> 342 | D33: =M12 -> 1770 | E33: =M18 -> 10 | F33: =M14 -> 291 | G33: =M13 -> 400 | H33: =M17 -> 486 | I33: =M16 -> 20.2 | J33: =M19 -> 0.4
B34: =B33-C29 -> 6632.4978 | C34: =C33-D29 -> 340.77112 | D34: =D33-E29 -> 1761.0569 | E34: =E33-G29 -> 3.4446379 | F34: =F33-J29 -> 284.59744 | G34: =G33-F29 -> 399.78487 | H34: =H33-I29 -> 485.62882 | I34: =I33-H29 -> 19.15935 | J34: =J33-K29 -> 0.28787666
